<?xml version="1.0"?>
<robot name="my_robot">

  <material name="grey"><color rgba="0.6 0.6 0.6 1"/></material>
  <material name="black"><color rgba="0.1 0.1 0.1 1"/></material>
  <material name="red"><color rgba="0.8 0.1 0.1 1"/></material>

  <!-- ================= BASE ================= -->
  <link name="base_link">
    <visual>
      <geometry><box size="0.4 0.3 0.15"/></geometry>
      <material name="grey"/>
    </visual>
    <collision>
      <geometry><box size="0.4 0.3 0.15"/></geometry>
    </collision>
    <inertial>
      <mass value="5.0"/>
      <inertia ixx="0.05" ixy="0.0" ixz="0.0" iyy="0.08" iyz="0.0" izz="0.1"/>
    </inertial>
  </link>

  <!-- ================= WHEEL MACRO (manual, 4x) ================= -->

  <!-- FRONT LEFT -->
  <link name="front_left_wheel">
    <visual>
      <geometry><cylinder radius="0.08" length="0.05"/></geometry>
      <material name="black"/>
    </visual>
    <collision>
      <geometry><cylinder radius="0.08" length="0.05"/></geometry>
    </collision>
    <inertial>
      <mass value="0.5"/>
      <inertia ixx="0.001" ixy="0.0" ixz="0.0" iyy="0.001" iyz="0.0" izz="0.001"/>
    </inertial>
  </link>
  <joint name="front_left_wheel_joint" type="continuous">
    <parent link="base_link"/>
    <child link="front_left_wheel"/>
    <origin xyz="0.15 0.175 -0.05" rpy="-1.5708 0 0"/>
    <axis xyz="0 0 1"/>
  </joint>

  <!-- FRONT RIGHT -->
  <link name="front_right_wheel">
    <visual>
      <geometry><cylinder radius="0.08" length="0.05"/></geometry>
      <material name="black"/>
    </visual>
    <collision>
      <geometry><cylinder radius="0.08" length="0.05"/></geometry>
    </collision>
    <inertial>
      <mass value="0.5"/>
      <inertia ixx="0.001" ixy="0.0" ixz="0.0" iyy="0.001" iyz="0.0" izz="0.001"/>
    </inertial>
  </link>
  <joint name="front_right_wheel_joint" type="continuous">
    <parent link="base_link"/>
    <child link="front_right_wheel"/>
    <origin xyz="0.15 -0.175 -0.05" rpy="-1.5708 0 0"/>
    <axis xyz="0 0 1"/>
  </joint>

  <!-- REAR LEFT -->
  <link name="rear_left_wheel">
    <visual>
      <geometry><cylinder radius="0.08" length="0.05"/></geometry>
      <material name="black"/>
    </visual>
    <collision>
      <geometry><cylinder radius="0.08" length="0.05"/></geometry>
    </collision>
    <inertial>
      <mass value="0.5"/>
      <inertia ixx="0.001" ixy="0.0" ixz="0.0" iyy="0.001" iyz="0.0" izz="0.001"/>
    </inertial>
  </link>
  <joint name="rear_left_wheel_joint" type="continuous">
    <parent link="base_link"/>
    <child link="rear_left_wheel"/>
    <origin xyz="-0.15 0.175 -0.05" rpy="-1.5708 0 0"/>
    <axis xyz="0 0 1"/>
  </joint>

  <!-- REAR RIGHT -->
  <link name="rear_right_wheel">
    <visual>
      <geometry><cylinder radius="0.08" length="0.05"/></geometry>
      <material name="black"/>
    </visual>
    <collision>
      <geometry><cylinder radius="0.08" length="0.05"/></geometry>
    </collision>
    <inertial>
      <mass value="0.5"/>
      <inertia ixx="0.001" ixy="0.0" ixz="0.0" iyy="0.001" iyz="0.0" izz="0.001"/>
    </inertial>
  </link>
  <joint name="rear_right_wheel_joint" type="continuous">
    <parent link="base_link"/>
    <child link="rear_right_wheel"/>
    <origin xyz="-0.15 -0.175 -0.05" rpy="-1.5708 0 0"/>
    <axis xyz="0 0 1"/>
  </joint>

  <!-- ================= LIDAR ================= -->
  <link name="lidar_link">
    <visual>
      <geometry><cylinder radius="0.04" length="0.06"/></geometry>
      <material name="red"/>
    </visual>
    <collision>
      <geometry><cylinder radius="0.04" length="0.06"/></geometry>
    </collision>
    <inertial>
      <mass value="0.1"/>
      <inertia ixx="0.0001" ixy="0.0" ixz="0.0" iyy="0.0001" iyz="0.0" izz="0.0001"/>
    </inertial>
  </link>
  <joint name="lidar_joint" type="fixed">
    <parent link="base_link"/>
    <child link="lidar_link"/>
    <origin xyz="0.1 0 0.105" rpy="0 0 0"/>
  </joint>

  <!-- ================= GAZEBO SENSOR: LIDAR ================= -->
  <gazebo reference="lidar_link">
    <sensor name="gpu_lidar" type="gpu_lidar">
      <pose>0 0 0 0 0 0</pose>
      <topic>scan</topic>
      <gz_frame_id>lidar_link</gz_frame_id>
      <update_rate>10</update_rate>
      <always_on>true</always_on>
      <visualize>true</visualize>
      <lidar>
        <scan>
          <horizontal>
            <samples>360</samples>
            <resolution>1</resolution>
            <min_angle>-3.14159</min_angle>
            <max_angle>3.14159</max_angle>
          </horizontal>
        </scan>
        <range>
          <min>0.12</min>
          <max>12.0</max>
          <resolution>0.015</resolution>
        </range>
      </lidar>
    </sensor>
  </gazebo>

  <!-- ================= GAZEBO PLUGIN: 4-WHEEL SKID STEER DRIVE ================= -->
  <gazebo>
    <plugin filename="gz-sim-diff-drive-system" name="gz::sim::systems::DiffDrive">
      <left_joint>front_left_wheel_joint</left_joint>
      <left_joint>rear_left_wheel_joint</left_joint>
      <right_joint>front_right_wheel_joint</right_joint>
      <right_joint>rear_right_wheel_joint</right_joint>
      <wheel_separation>0.35</wheel_separation>
      <wheel_radius>0.08</wheel_radius>
      <topic>cmd_vel</topic>
    </plugin>

    <!-- Ground-truth odometry: bypasses the skid-steer wheel-scrub error that
         the DiffDrive plugin's own kinematic odom estimate can't account for
         (4 rigid wheels forced to scrub sideways when turning, but no
         <friction> tuning and no caster — the ideal 2-wheel diff-drive model
         doesn't match this chassis). Using this while we validate the rest
         of the nav stack; real wheel-based odom can come back once the
         drivetrain itself is revisited. -->
    <plugin filename="gz-sim-odometry-publisher-system" name="gz::sim::systems::OdometryPublisher">
      <odom_frame>odom</odom_frame>
      <robot_base_frame>base_link</robot_base_frame>
      <odom_topic>odom</odom_topic>
      <odom_publish_frequency>30</odom_publish_frequency>
      <tf_topic>/tf</tf_topic>
    </plugin>

    <plugin filename="gz-sim-joint-state-publisher-system" name="gz::sim::systems::JointStatePublisher">
      <topic>joint_states</topic>
    </plugin>
  </gazebo>

</robot>
